Workbook

Sheet Assumptions
A1: Assumptions: synthetic quick-commerce dark store, calibrated to Swiggy Instamart Q2 FY27 (quarter ended 30-Sep-2026)
A2: The store is synthetic. Totals are anchored to the company letters; the split of those totals across cost lines is NOT disclosed and is a labelled synthetic allocation. Results are modeled scenarios, not company measurements.
A4: Legend: | B4: Blue = typed input | C4: Black = formula | D4: Green = link to another sheet | E4: Yellow fill = scenario lever (edit these)
A5: All numbers in the two P&L sheets are formulas that point to this sheet. To test a scenario change only the yellow cells in section 4.
A7: ID (in assumptions.csv) | B7: Item | C7: Value | D7: Unit | E7: Type | F7: Source / how derived | G7: Page | H7: Source URL
A8: 1. Reported anchors (company letters; each ID matches data/assumptions.csv)
A9: I01 | B9: Net order value per order (nAOV), Swiggy Instamart | C9: 506 | D9: INR/order | E9: Reported | F9: Swiggy Q2 FY27 Shareholders' Letter, 22-Oct-2026 | G9: 4 | H9: https://www.swiggy.com/corporate/wp-content/uploads/2026/10/Covering-Letter_Letter-to-Shareholders-Signed.pdf
A10: I11 | B10: Orders per dark store per day | C10: 1192 | D10: orders/store/day | E10: Reported | F10: Swiggy Q2 FY27 Shareholders' Letter, 22-Oct-2026 | G10: 7 | H10: https://www.swiggy.com/corporate/wp-content/uploads/2026/10/Covering-Letter_Letter-to-Shareholders-Signed.pdf
A11: I02 | B11: Orders in quarter | C11: 130.3 | D11: million | E11: Reported | F11: Swiggy Q2 FY27 Shareholders' Letter, 22-Oct-2026 | G11: 7 | H11: https://www.swiggy.com/corporate/wp-content/uploads/2026/10/Covering-Letter_Letter-to-Shareholders-Signed.pdf
A12: I03 | B12: Gross order value (GOV) in quarter | C12: 9230 | D12: INR crore | E12: Reported | F12: Swiggy Q2 FY27 Shareholders' Letter, 22-Oct-2026 | G12: 4, 7 | H12: https://www.swiggy.com/corporate/wp-content/uploads/2026/10/Covering-Letter_Letter-to-Shareholders-Signed.pdf
A13: I17 | B13: Quick-commerce Adjusted Revenue in quarter | C13: 1307 | D13: INR crore | E13: Reported | F13: Swiggy Q2 FY27 Shareholders' Letter, 22-Oct-2026 | G13: 7 | H13: https://www.swiggy.com/corporate/wp-content/uploads/2026/10/Covering-Letter_Letter-to-Shareholders-Signed.pdf
A14: I07 | B14: Contribution margin | C14: -0.01 | D14: % of GOV | E14: Reported | F14: Swiggy Q2 FY27 Shareholders' Letter, 22-Oct-2026 | G14: 4, 7 | H14: https://www.swiggy.com/corporate/wp-content/uploads/2026/10/Covering-Letter_Letter-to-Shareholders-Signed.pdf
A15: I13 | B15: Break-even benchmark: contribution per order needed for adjusted EBITDA break-even | C15: 30 | D15: INR/order | E15: Reported (mgmt guidance) | F15: Swiggy Q2 FY27 Shareholders' Letter, 22-Oct-2026 | G15: 13 | H15: https://www.swiggy.com/corporate/wp-content/uploads/2026/10/Covering-Letter_Letter-to-Shareholders-Signed.pdf
A16: 2. Derived from the anchors (formulas)
B17: GOV per order | C17: =$C$12*10000000/($C$11*1000000) -> 708.36531 | D17: INR/order | E17: Derived | F17: GOV / orders
B18: Adjusted revenue per order (after product cost) | C18: =$C$13*10000000/($C$11*1000000) -> 100.30698 | D18: INR/order | E18: Derived | F18: Adjusted revenue / orders
B19: Reported store contribution per order | C19: =$C$14*$C$17 -> -7.0836531 | D19: INR/order | E19: Derived | F19: Contribution margin x GOV per order (same as I12 in CSV)
B20: All-in cost per order (variable + store costs, as the company defines contribution) | C20: =$C$18-$C$19 -> 107.39064 | D20: INR/order | E20: Derived | F20: Adjusted revenue per order less contribution per order
A21: 3. Synthetic allocation (NOT disclosed by the company; judgement, adjustable)
A22: S1 | B22: Share of adjusted revenue from product margin / commission | C22: 0.6 | D22: % of adjusted revenue | E22: Synthetic | F22: Allocation of the anchored total. Company does not split it
A23: S2 | B23: Share of adjusted revenue from ad income | C23: 0.2 | D23: % of adjusted revenue | E23: Synthetic | F23: Same
B24: Share of adjusted revenue from customer fees (residual) | C24: =1-$C$22-$C$23 -> 0.2 | D24: % of adjusted revenue | E24: Derived | F24: Residual so the three shares sum to 100%
A25: S3 | B25: Share of all-in cost: platform-funded discounts | C25: 0.12 | D25: % of all-in cost | E25: Synthetic | F25: Allocation of the anchored total
A26: S4 | B26: Share of all-in cost: last-mile delivery | C26: 0.4 | D26: % of all-in cost | E26: Synthetic | F26: Same
A27: S5 | B27: Share of all-in cost: picking and packing | C27: 0.15 | D27: % of all-in cost | E27: Synthetic | F27: Same
A28: S6 | B28: Share of all-in cost: payment and other per-order costs | C28: 0.08 | D28: % of all-in cost | E28: Synthetic | F28: Same
B29: Share of all-in cost: dark store fixed costs (residual) | C29: =1-$C$25-$C$26-$C$27-$C$28 -> 0.25 | D29: % of all-in cost | E29: Derived | F29: Residual: rent, fixed staff, utilities
A30: S7 | B30: Days per month | C30: 30 | D30: days | E30: Synthetic | F30: Convention for the monthly column
A31: 4. Scenario levers (0% = base case; Day 3 will flex these)
A32: L1 | B32: Change in order value (NOV per order) | C32: 0 | D32: % change | E32: Scenario lever | F32: Base case = 0%
A33: L2 | B33: Change in orders per day | C33: 0 | D33: % change | E33: Scenario lever | F33: Base case = 0%
A34: L3 | B34: Change in delivery cost per order | C34: 0 | D34: % change | E34: Scenario lever | F34: Base case = 0%
A35: L4 | B35: Change in ad income per order | C35: 0 | D35: % change | E35: Scenario lever | F35: Base case = 0%
A36: 5. Model inputs per order, derived (formulas)
B37: Product margin as % of NOV | C37: =$C$22*$C$18/$C$9 -> 0.11894109 | D37: % of NOV | E37: Derived | F37: Product margin share x adjusted revenue / base NOV
B38: Ad income per order (base) | C38: =$C$23*$C$18 -> 20.061397 | D38: INR/order | E38: Derived
B39: Customer fees per order | C39: =$C$24*$C$18 -> 20.061397 | D39: INR/order | E39: Derived
B40: Platform-funded discounts per order | C40: =$C$25*$C$20 -> 12.886876 | D40: INR/order | E40: Derived
B41: Delivery cost per order (base) | C41: =$C$26*$C$20 -> 42.956255 | D41: INR/order | E41: Derived
B42: Picking and packing per order | C42: =$C$27*$C$20 -> 16.108596 | D42: INR/order | E42: Derived
...

Sheet Per-order P&L
A1: Per-order P&L (INR per order)
A2: Synthetic dark store, base case calibrated to Swiggy Instamart Q2 FY27. Every number below is a formula that points to the Assumptions sheet.
A3: CM1 and CM2: CM1 is what an order earns after the product and the discounts, meaning net order value less product cost (the seller's or supplier's share), plus the ad income and customer fees the platform collects, less platform-funded discounts. CM2 is CM1 less the variable cost of fulfilling the order: picking, packing, last-mile delivery, and payment and other per-order costs. Dark store fixed costs (rent, fixed staff, utilities) sit below CM2 and are spread over the day's orders; CM2 less that charge is the store contribution per order, which matches the way the companies report contribution. Central costs such as technology, brand marketing and corporate overhead are excluded.
A5: Line | B5: INR per order | C5: % of NOV | D5: How it is built
A6: Net order value (NOV) | B6: =Assumptions!$C$46 -> 506 | C6: =IF($B$6=0,0,B6/$B$6) -> 1 | D6: NOV per order used (base 506 x (1 + order value lever))
A7: Less: product cost / seller share | B7: =-B6*(1-Assumptions!$C$37) -> -445.81581 | C7: =IF($B$6=0,0,B7/$B$6) -> -0.88105891 | D7: NOV x (1 - product margin %)
A8: Product margin / commission | B8: =B6+B7 -> 60.18419 | C8: =IF($B$6=0,0,B8/$B$6) -> 0.11894109 | D8: NOV less product cost
A9: Ad income | B9: =Assumptions!$C$49 -> 20.061397 | C9: =IF($B$6=0,0,B9/$B$6) -> 0.039647029 | D9: Ad income per order used
A10: Customer fees (delivery, handling, platform) | B10: =Assumptions!$C$39 -> 20.061397 | C10: =IF($B$6=0,0,B10/$B$6) -> 0.039647029 | D10: Customer fees per order
A11: Revenue after product cost | B11: =B8+B9+B10 -> 100.30698 | C11: =IF($B$6=0,0,B11/$B$6) -> 0.19823515 | D11: Matches Swiggy's Adjusted Revenue per order in the base case
A12: Less: platform-funded discounts | B12: =-Assumptions!$C$40 -> -12.886876 | C12: =IF($B$6=0,0,B12/$B$6) -> -0.025468135
A13: CM1 | B13: =B11+B12 -> 87.420107 | C13: =IF($B$6=0,0,B13/$B$6) -> 0.17276701 | D13: Revenue after product cost and discounts
A14: Less: picking and packing | B14: =-Assumptions!$C$42 -> -16.108596 | C14: =IF($B$6=0,0,B14/$B$6) -> -0.031835169
A15: Less: last-mile delivery | B15: =-Assumptions!$C$48 -> -42.956255 | C15: =IF($B$6=0,0,B15/$B$6) -> -0.084893784 | D15: Delivery cost per order used
A16: Less: payment and other per-order costs | B16: =-B6*Assumptions!$C$43 -> -8.591251 | C16: =IF($B$6=0,0,B16/$B$6) -> -0.016978757 | D16: % of NOV, scales with order value
A17: CM2 | B17: =B13+B14+B15+B16 -> 19.764006 | C17: =IF($B$6=0,0,B17/$B$6) -> 0.039059301 | D17: CM1 less picking, packing, delivery, payment
A18: Less: dark store fixed cost per order | B18: =IF(Assumptions!$C$47=0,0,-Assumptions!$C$44/Assumptions!$C$47) -> -26.847659 | C18: =IF($B$6=0,0,B18/$B$6) -> -0.053058615 | D18: Fixed cost per day / orders per day used
A19: Store contribution per order | B19: =B17+B18 -> -7.0836531 | C19: =IF($B$6=0,0,B19/$B$6) -> -0.013999314 | D19: CM2 less fixed store cost. Negative = the store loses money on each order
A21: Memo and checks
A22: Reported store contribution per order (Swiggy, derived) | B22: =Assumptions!$C$19 -> -7.0836531
A23: Model less reported (0 in the base case) | B23: =B19-B22 -> 0 | D23: Zero only while all four levers are 0%
A24: Break-even benchmark per order (Swiggy guidance) | B24: =Assumptions!$C$15 -> 30
A25: Store contribution per order less benchmark | B25: =B19-B24 -> -37.083653 | D25: Negative = gap that levers must close
A26: Reference: Blinkit contribution per order (Q2 FY27, derived) | B26: =Assumptions!$C$51 -> 28

Sheet Store daily P&L
A1: Store daily P&L (INR)
A2: One synthetic dark store. Per-day lines = orders per day x per-order line; fixed cost is charged once per day.
A4: Orders per day | B4: =Assumptions!$C$47 -> 1192 | C4: =B4*Assumptions!$C$30 -> 35760
A5: Line | B5: INR per day | C5: INR per month | D5: How it is built
A6: Net order value (NOV) | B6: =$B$4*'Per-order P&L'!B6 -> 603152 | C6: =B6*Assumptions!$C$30 -> 18094560 | D6: Orders per day x per-order line (Per-order P&L row 6)
A7: Less: product cost / seller share | B7: =$B$4*'Per-order P&L'!B7 -> -531412.45 | C7: =B7*Assumptions!$C$30 -> -15942373 | D7: Orders per day x per-order line (Per-order P&L row 7)
A8: Product margin / commission | B8: =$B$4*'Per-order P&L'!B8 -> 71739.555 | C8: =B8*Assumptions!$C$30 -> 2152186.6 | D8: Orders per day x per-order line (Per-order P&L row 8)
A9: Ad income | B9: =$B$4*'Per-order P&L'!B9 -> 23913.185 | C9: =B9*Assumptions!$C$30 -> 717395.55 | D9: Orders per day x per-order line (Per-order P&L row 9)
A10: Customer fees (delivery, handling, platform) | B10: =$B$4*'Per-order P&L'!B10 -> 23913.185 | C10: =B10*Assumptions!$C$30 -> 717395.55 | D10: Orders per day x per-order line (Per-order P&L row 10)
A11: Revenue after product cost | B11: =$B$4*'Per-order P&L'!B11 -> 119565.92 | C11: =B11*Assumptions!$C$30 -> 3586977.7 | D11: Orders per day x per-order line (Per-order P&L row 11)
A12: Less: platform-funded discounts | B12: =$B$4*'Per-order P&L'!B12 -> -15361.157 | C12: =B12*Assumptions!$C$30 -> -460834.7 | D12: Orders per day x per-order line (Per-order P&L row 12)
A13: CM1 | B13: =$B$4*'Per-order P&L'!B13 -> 104204.77 | C13: =B13*Assumptions!$C$30 -> 3126143 | D13: Orders per day x per-order line (Per-order P&L row 13)
A14: Less: picking and packing | B14: =$B$4*'Per-order P&L'!B14 -> -19201.446 | C14: =B14*Assumptions!$C$30 -> -576043.38 | D14: Orders per day x per-order line (Per-order P&L row 14)
A15: Less: last-mile delivery | B15: =$B$4*'Per-order P&L'!B15 -> -51203.856 | C15: =B15*Assumptions!$C$30 -> -1536115.7 | D15: Orders per day x per-order line (Per-order P&L row 15)
A16: Less: payment and other per-order costs | B16: =$B$4*'Per-order P&L'!B16 -> -10240.771 | C16: =B16*Assumptions!$C$30 -> -307223.13 | D16: Orders per day x per-order line (Per-order P&L row 16)
A17: CM2 | B17: =$B$4*'Per-order P&L'!B17 -> 23558.695 | C17: =B17*Assumptions!$C$30 -> 706760.86 | D17: Orders per day x per-order line (Per-order P&L row 17)
A18: Less: dark store fixed cost per day | B18: =-Assumptions!$C$44 -> -32002.41 | C18: =B18*Assumptions!$C$30 -> -960072.29 | D18: Fixed cost per day, charged once
A19: Store contribution per order | B19: =$B$4*'Per-order P&L'!B19 -> -8443.7145 | C19: =B19*Assumptions!$C$30 -> -253311.44 | D19: Negative = the store loses money per day
A21: Memo and checks
A22: Store contribution per order (daily total / orders) | B22: =IF(B4=0,0,B19/B4) -> -7.0836531
A23: Difference vs Per-order P&L (should be 0) | B23: =B22-'Per-order P&L'!B19 -> 0

Sheet Break-even
A1: Break-even (store level, INR)
A2: All figures start from the base case on the Assumptions sheet and ignore the scenario levers. Modeled scenario estimates for a synthetic store, not company measurements.
A4: A. Break-even orders per store per day (everything else at base case)
A5: Item | B5: Value | C5: Note
A6: Dark store fixed cost per day | B6: =Assumptions!$C$44 -> 32002.41 | C6: INR/day
A7: CM2 per order at base | B7: =Assumptions!$C$66 -> 19.764006 | C7: INR/order: what each extra order contributes toward fixed cost
A8: Break-even orders per store per day | B8: =IF(B7<=0,"No break-even: CM2 is not positive",B6/B7) -> 1619.2269 | C8: Fixed cost per day / CM2 per order
A9: Base orders per store per day | B9: =Assumptions!$C$10 -> 1192 | C9: Instamart Q2 FY27, reported
A10: Extra orders needed per day | B10: =IF(ISNUMBER(B8),B8-B9,"n/a") -> 427.22687
A11: Increase needed in orders per day | B11: =IF(ISNUMBER(B8),IF(B9=0,0,B8/B9-1),"n/a") -> 0.3584118
A12: Reference: Blinkit orders per store per day | B12: =Assumptions!$C$53 -> 1718 | C12: Derived from Eternal's NOV per store per day / NAOV; not a reported figure
A13: Break-even volume less Blinkit reference | B13: =IF(ISNUMBER(B8),B8-B12,"n/a") -> -98.773129 | C13: Negative = break-even volume is below what Blinkit stores already do
A15: B. Break-even by single lever (one lever moves, all others stay at base)
A16: Lever | B16: Base value | C16: Break-even value | D16: Change needed | E16: % change | F16: Unit
A17: Order value (NOV per order) | B17: =Assumptions!$C$9 -> 506 | C17: =IF(Assumptions!$C$63<=0,"n/a",B17-Assumptions!$C$67/Assumptions!$C$63) -> 575.47324 | D17: =IF(ISNUMBER(C17),C17-B17,"n/a") -> 69.473236 | E17: =IF(ISNUMBER(C17),IF(B17=0,0,C17/B17-1),"n/a") -> 0.13729889 | F17: INR/order
A18: Orders per day | B18: =Assumptions!$C$10 -> 1192 | C18: =B8 -> 1619.2269 | D18: =IF(ISNUMBER(C18),C18-B18,"n/a") -> 427.22687 | E18: =IF(ISNUMBER(C18),IF(B18=0,0,C18/B18-1),"n/a") -> 0.3584118 | F18: orders/day
A19: Delivery cost per order (needs to fall) | B19: =Assumptions!$C$41 -> 42.956255 | C19: =B19+Assumptions!$C$67 -> 35.872602 | D19: =IF(ISNUMBER(C19),C19-B19,"n/a") -> -7.0836531 | E19: =IF(ISNUMBER(C19),IF(B19=0,0,C19/B19-1),"n/a") -> -0.16490388 | F19: INR/order
A20: Ad income per order | B20: =Assumptions!$C$38 -> 20.061397 | C20: =B20-Assumptions!$C$67 -> 27.14505 | D20: =IF(ISNUMBER(C20),C20-B20,"n/a") -> 7.0836531 | E20: =IF(ISNUMBER(C20),IF(B20=0,0,C20/B20-1),"n/a") -> 0.3530987 | F20: INR/order
A22: How to read: the store loses money per order at base. Each row shows how far that single lever alone would have to move to reach zero store contribution. Levers can be combined, which needs smaller moves in each.

Sheet Sensitivity
A1: Sensitivity tables: store contribution per day (INR per store per day)
A2: Base case on the Assumptions sheet, scenario levers ignored. Green = store profit, red = store loss. Modeled scenario estimates for a synthetic store, not company measurements.
A4: Table 1. Order value x orders per day
A5: Order value change (down) / orders per day change (across) | B5: NOV, INR/order | C5: =Assumptions!$C$57 -> -0.2 | D5: =C5+Assumptions!$C$58 -> -0.1 | E5: =D5+Assumptions!$C$58 -> 0 | F5: =E5+Assumptions!$C$58 -> 0.1 | G5: =F5+Assumptions!$C$58 -> 0.2 | H5: =G5+Assumptions!$C$58 -> 0.3 | I5: =H5+Assumptions!$C$58 -> 0.4
B6: Orders per day | C6: =Assumptions!$C$10*(1+C5) -> 953.6 | D6: =Assumptions!$C$10*(1+D5) -> 1072.8 | E6: =Assumptions!$C$10*(1+E5) -> 1192 | F6: =Assumptions!$C$10*(1+F5) -> 1311.2 | G6: =Assumptions!$C$10*(1+G5) -> 1430.4 | H6: =Assumptions!$C$10*(1+H5) -> 1549.6 | I6: =Assumptions!$C$10*(1+I5) -> 1668.8
A7: =Assumptions!$C$55 -> -0.1 | B7: =Assumptions!$C$9*(1+A7) -> 455.4 | C7: =C$6*(Assumptions!$C$63*$B7+Assumptions!$C$64-Assumptions!$C$41)-Assumptions!$C$44 -> -18075.356 | D7: =D$6*(Assumptions!$C$63*$B7+Assumptions!$C$64-Assumptions!$C$41)-Assumptions!$C$44 -> -16334.475 | E7: =E$6*(Assumptions!$C$63*$B7+Assumptions!$C$64-Assumptions!$C$41)-Assumptions!$C$44 -> -14593.593 | F7: =F$6*(Assumptions!$C$63*$B7+Assumptions!$C$64-Assumptions!$C$41)-Assumptions!$C$44 -> -12852.711 | G7: =G$6*(Assumptions!$C$63*$B7+Assumptions!$C$64-Assumptions!$C$41)-Assumptions!$C$44 -> -11111.829 | H7: =H$6*(Assumptions!$C$63*$B7+Assumptions!$C$64-Assumptions!$C$41)-Assumptions!$C$44 -> -9370.9478 | I7: =I$6*(Assumptions!$C$63*$B7+Assumptions!$C$64-Assumptions!$C$41)-Assumptions!$C$44 -> -7630.0661
A8: =A7+Assumptions!$C$56 -> -0.05 | B8: =Assumptions!$C$9*(1+A8) -> 480.7 | C8: =C$6*(Assumptions!$C$63*$B8+Assumptions!$C$64-Assumptions!$C$41)-Assumptions!$C$44 -> -15615.405 | D8: =D$6*(Assumptions!$C$63*$B8+Assumptions!$C$64-Assumptions!$C$41)-Assumptions!$C$44 -> -13567.029 | E8: =E$6*(Assumptions!$C$63*$B8+Assumptions!$C$64-Assumptions!$C$41)-Assumptions!$C$44 -> -11518.654 | F8: =F$6*(Assumptions!$C$63*$B8+Assumptions!$C$64-Assumptions!$C$41)-Assumptions!$C$44 -> -9470.2781 | G8: =G$6*(Assumptions!$C$63*$B8+Assumptions!$C$64-Assumptions!$C$41)-Assumptions!$C$44 -> -7421.9025 | H8: =H$6*(Assumptions!$C$63*$B8+Assumptions!$C$64-Assumptions!$C$41)-Assumptions!$C$44 -> -5373.5269 | I8: =I$6*(Assumptions!$C$63*$B8+Assumptions!$C$64-Assumptions!$C$41)-Assumptions!$C$44 -> -3325.1512
A9: =A8+Assumptions!$C$56 -> 0 | B9: =Assumptions!$C$9*(1+A9) -> 506 | C9: =C$6*(Assumptions!$C$63*$B9+Assumptions!$C$64-Assumptions!$C$41)-Assumptions!$C$44 -> -13155.454 | D9: =D$6*(Assumptions!$C$63*$B9+Assumptions!$C$64-Assumptions!$C$41)-Assumptions!$C$44 -> -10799.584 | E9: =E$6*(Assumptions!$C$63*$B9+Assumptions!$C$64-Assumptions!$C$41)-Assumptions!$C$44 -> -8443.7145 | F9: =F$6*(Assumptions!$C$63*$B9+Assumptions!$C$64-Assumptions!$C$41)-Assumptions!$C$44 -> -6087.845 | G9: =G$6*(Assumptions!$C$63*$B9+Assumptions!$C$64-Assumptions!$C$41)-Assumptions!$C$44 -> -3731.9754 | H9: =H$6*(Assumptions!$C$63*$B9+Assumptions!$C$64-Assumptions!$C$41)-Assumptions!$C$44 -> -1376.1059 | I9: =I$6*(Assumptions!$C$63*$B9+Assumptions!$C$64-Assumptions!$C$41)-Assumptions!$C$44 -> 979.76362
A10: =A9+Assumptions!$C$56 -> 0.05 | B10: =Assumptions!$C$9*(1+A10) -> 531.3 | C10: =C$6*(Assumptions!$C$63*$B10+Assumptions!$C$64-Assumptions!$C$41)-Assumptions!$C$44 -> -10695.502 | D10: =D$6*(Assumptions!$C$63*$B10+Assumptions!$C$64-Assumptions!$C$41)-Assumptions!$C$44 -> -8032.1388 | E10: =E$6*(Assumptions!$C$63*$B10+Assumptions!$C$64-Assumptions!$C$41)-Assumptions!$C$44 -> -5368.7753 | F10: =F$6*(Assumptions!$C$63*$B10+Assumptions!$C$64-Assumptions!$C$41)-Assumptions!$C$44 -> -2705.4119 | G10: =G$6*(Assumptions!$C$63*$B10+Assumptions!$C$64-Assumptions!$C$41)-Assumptions!$C$44 -> -42.048417 | H10: =H$6*(Assumptions!$C$63*$B10+Assumptions!$C$64-Assumptions!$C$41)-Assumptions!$C$44 -> 2621.315 | I10: =I$6*(Assumptions!$C$63*$B10+Assumptions!$C$64-Assumptions!$C$41)-Assumptions!$C$44 -> 5284.6785
A11: =A10+Assumptions!$C$56 -> 0.1 | B11: =Assumptions!$C$9*(1+A11) -> 556.6 | C11: =C$6*(Assumptions!$C$63*$B11+Assumptions!$C$64-Assumptions!$C$41)-Assumptions!$C$44 -> -8235.5509 | D11: =D$6*(Assumptions!$C$63*$B11+Assumptions!$C$64-Assumptions!$C$41)-Assumptions!$C$44 -> -5264.6935 | E11: =E$6*(Assumptions!$C$63*$B11+Assumptions!$C$64-Assumptions!$C$41)-Assumptions!$C$44 -> -2293.8361 | F11: =F$6*(Assumptions!$C$63*$B11+Assumptions!$C$64-Assumptions!$C$41)-Assumptions!$C$44 -> 677.02124 | G11: =G$6*(Assumptions!$C$63*$B11+Assumptions!$C$64-Assumptions!$C$41)-Assumptions!$C$44 -> 3647.8786 | H11: =H$6*(Assumptions!$C$63*$B11+Assumptions!$C$64-Assumptions!$C$41)-Assumptions!$C$44 -> 6618.736 | I11: =I$6*(Assumptions!$C$63*$B11+Assumptions!$C$64-Assumptions!$C$41)-Assumptions!$C$44 -> 9589.5933
A12: =A11+Assumptions!$C$56 -> 0.15 | B12: =Assumptions!$C$9*(1+A12) -> 581.9 | C12: =C$6*(Assumptions!$C$63*$B12+Assumptions!$C$64-Assumptions!$C$41)-Assumptions!$C$44 -> -5775.5995 | D12: =D$6*(Assumptions!$C$63*$B12+Assumptions!$C$64-Assumptions!$C$41)-Assumptions!$C$44 -> -2497.2482 | E12: =E$6*(Assumptions!$C$63*$B12+Assumptions!$C$64-Assumptions!$C$41)-Assumptions!$C$44 -> 781.10305 | F12: =F$6*(Assumptions!$C$63*$B12+Assumptions!$C$64-Assumptions!$C$41)-Assumptions!$C$44 -> 4059.4543 | G12: =G$6*(Assumptions!$C$63*$B12+Assumptions!$C$64-Assumptions!$C$41)-Assumptions!$C$44 -> 7337.8056 | H12: =H$6*(Assumptions!$C$63*$B12+Assumptions!$C$64-Assumptions!$C$41)-Assumptions!$C$44 -> 10616.157 | I12: =I$6*(Assumptions!$C$63*$B12+Assumptions!$C$64-Assumptions!$C$41)-Assumptions!$C$44 -> 13894.508
A13: =A12+Assumptions!$C$56 -> 0.2 | B13: =Assumptions!$C$9*(1+A13) -> 607.2 | C13: =C$6*(Assumptions!$C$63*$B13+Assumptions!$C$64-Assumptions!$C$41)-Assumptions!$C$44 -> -3315.6482 | D13: =D$6*(Assumptions!$C$63*$B13+Assumptions!$C$64-Assumptions!$C$41)-Assumptions!$C$44 -> 270.19703 | E13: =E$6*(Assumptions!$C$63*$B13+Assumptions!$C$64-Assumptions!$C$41)-Assumptions!$C$44 -> 3856.0422 | F13: =F$6*(Assumptions!$C$63*$B13+Assumptions!$C$64-Assumptions!$C$41)-Assumptions!$C$44 -> 7441.8874 | G13: =G$6*(Assumptions!$C$63*$B13+Assumptions!$C$64-Assumptions!$C$41)-Assumptions!$C$44 -> 11027.733 | H13: =H$6*(Assumptions!$C$63*$B13+Assumptions!$C$64-Assumptions!$C$41)-Assumptions!$C$44 -> 14613.578 | I13: =I$6*(Assumptions!$C$63*$B13+Assumptions!$C$64-Assumptions!$C$41)-Assumptions!$C$44 -> 18199.423
A16: Table 2. Delivery cost x order value
A17: Delivery cost change (down) / order value change (across) | B17: Delivery cost, INR/order | C17: =Assumptions!$C$55 -> -0.1 | D17: =C17+Assumptions!$C$56 -> -0.05 | E17: =D17+Assumptions!$C$56 -> 0 | F17: =E17+Assumptions!$C$56 -> 0.05 | G17: =F17+Assumptions!$C$56 -> 0.1 | H17: =G17+Assumptions!$C$56 -> 0.15 | I17: =H17+Assumptions!$C$56 -> 0.2
B18: NOV, INR/order | C18: =Assumptions!$C$9*(1+C17) -> 455.4 | D18: =Assumptions!$C$9*(1+D17) -> 480.7 | E18: =Assumptions!$C$9*(1+E17) -> 506 | F18: =Assumptions!$C$9*(1+F17) -> 531.3 | G18: =Assumptions!$C$9*(1+G17) -> 556.6 | H18: =Assumptions!$C$9*(1+H17) -> 581.9 | I18: =Assumptions!$C$9*(1+I17) -> 607.2
A19: =Assumptions!$C$59 -> -0.3 | B19: =Assumptions!$C$41*(1+A19) -> 30.069378 | C19: =Assumptions!$C$10*(Assumptions!$C$63*C$18+Assumptions!$C$64-$B19)-Assumptions!$C$44 -> 767.56384 | D19: =Assumptions!$C$10*(Assumptions!$C$63*D$18+Assumptions!$C$64-$B19)-Assumptions!$C$44 -> 3842.503 | E19: =Assumptions!$C$10*(Assumptions!$C$63*E$18+Assumptions!$C$64-$B19)-Assumptions!$C$44 -> 6917.4422 | F19: =Assumptions!$C$10*(Assumptions!$C$63*F$18+Assumptions!$C$64-$B19)-Assumptions!$C$44 -> 9992.3814 | G19: =Assumptions!$C$10*(Assumptions!$C$63*G$18+Assumptions!$C$64-$B19)-Assumptions!$C$44 -> 13067.321 | H19: =Assumptions!$C$10*(Assumptions!$C$63*H$18+Assumptions!$C$64-$B19)-Assumptions!$C$44 -> 16142.26 | I19: =Assumptions!$C$10*(Assumptions!$C$63*I$18+Assumptions!$C$64-$B19)-Assumptions!$C$44 -> 19217.199
A20: =A19+Assumptions!$C$60 -> -0.2 | B20: =Assumptions!$C$41*(1+A20) -> 34.365004 | C20: =Assumptions!$C$10*(Assumptions!$C$63*C$18+Assumptions!$C$64-$B20)-Assumptions!$C$44 -> -4352.8217 | D20: =Assumptions!$C$10*(Assumptions!$C$63*D$18+Assumptions!$C$64-$B20)-Assumptions!$C$44 -> -1277.8825 | E20: =Assumptions!$C$10*(Assumptions!$C$63*E$18+Assumptions!$C$64-$B20)-Assumptions!$C$44 -> 1797.0566 | F20: =Assumptions!$C$10*(Assumptions!$C$63*F$18+Assumptions!$C$64-$B20)-Assumptions!$C$44 -> 4871.9958 | G20: =Assumptions!$C$10*(Assumptions!$C$63*G$18+Assumptions!$C$64-$B20)-Assumptions!$C$44 -> 7946.935 | H20: =Assumptions!$C$10*(Assumptions!$C$63*H$18+Assumptions!$C$64-$B20)-Assumptions!$C$44 -> 11021.874 | I20: =Assumptions!$C$10*(Assumptions!$C$63*I$18+Assumptions!$C$64-$B20)-Assumptions!$C$44 -> 14096.813
A21: =A20+Assumptions!$C$60 -> -0.1 | B21: =Assumptions!$C$41*(1+A21) -> 38.660629 | C21: =Assumptions!$C$10*(Assumptions!$C$63*C$18+Assumptions!$C$64-$B21)-Assumptions!$C$44 -> -9473.2073 | D21: =Assumptions!$C$10*(Assumptions!$C$63*D$18+Assumptions!$C$64-$B21)-Assumptions!$C$44 -> -6398.2681 | E21: =Assumptions!$C$10*(Assumptions!$C$63*E$18+Assumptions!$C$64-$B21)-Assumptions!$C$44 -> -3323.3289 | F21: =Assumptions!$C$10*(Assumptions!$C$63*F$18+Assumptions!$C$64-$B21)-Assumptions!$C$44 -> -248.38975 | G21: =Assumptions!$C$10*(Assumptions!$C$63*G$18+Assumptions!$C$64-$B21)-Assumptions!$C$44 -> 2826.5494 | H21: =Assumptions!$C$10*(Assumptions!$C$63*H$18+Assumptions!$C$64-$B21)-Assumptions!$C$44 -> 5901.4886 | I21: =Assumptions!$C$10*(Assumptions!$C$63*I$18+Assumptions!$C$64-$B21)-Assumptions!$C$44 -> 8976.4278
A22: =A21+Assumptions!$C$60 -> 0 | B22: =Assumptions!$C$41*(1+A22) -> 42.956255 | C22: =Assumptions!$C$10*(Assumptions!$C$63*C$18+Assumptions!$C$64-$B22)-Assumptions!$C$44 -> -14593.593 | D22: =Assumptions!$C$10*(Assumptions!$C$63*D$18+Assumptions!$C$64-$B22)-Assumptions!$C$44 -> -11518.654 | E22: =Assumptions!$C$10*(Assumptions!$C$63*E$18+Assumptions!$C$64-$B22)-Assumptions!$C$44 -> -8443.7145 | F22: =Assumptions!$C$10*(Assumptions!$C$63*F$18+Assumptions!$C$64-$B22)-Assumptions!$C$44 -> -5368.7753 | G22: =Assumptions!$C$10*(Assumptions!$C$63*G$18+Assumptions!$C$64-$B22)-Assumptions!$C$44 -> -2293.8361 | H22: =Assumptions!$C$10*(Assumptions!$C$63*H$18+Assumptions!$C$64-$B22)-Assumptions!$C$44 -> 781.10305 | I22: =Assumptions!$C$10*(Assumptions!$C$63*I$18+Assumptions!$C$64-$B22)-Assumptions!$C$44 -> 3856.0422
A23: =A22+Assumptions!$C$60 -> 0.1 | B23: =Assumptions!$C$41*(1+A23) -> 47.25188 | C23: =Assumptions!$C$10*(Assumptions!$C$63*C$18+Assumptions!$C$64-$B23)-Assumptions!$C$44 -> -19713.978 | D23: =Assumptions!$C$10*(Assumptions!$C$63*D$18+Assumptions!$C$64-$B23)-Assumptions!$C$44 -> -16639.039 | E23: =Assumptions!$C$10*(Assumptions!$C$63*E$18+Assumptions!$C$64-$B23)-Assumptions!$C$44 -> -13564.1 | F23: =Assumptions!$C$10*(Assumptions!$C$63*F$18+Assumptions!$C$64-$B23)-Assumptions!$C$44 -> -10489.161 | G23: =Assumptions!$C$10*(Assumptions!$C$63*G$18+Assumptions!$C$64-$B23)-Assumptions!$C$44 -> -7414.2217 | H23: =Assumptions!$C$10*(Assumptions!$C$63*H$18+Assumptions!$C$64-$B23)-Assumptions!$C$44 -> -4339.2825 | I23: =Assumptions!$C$10*(Assumptions!$C$63*I$18+Assumptions!$C$64-$B23)-Assumptions!$C$44 -> -1264.3433
A24: =A23+Assumptions!$C$60 -> 0.2 | B24: =Assumptions!$C$41*(1+A24) -> 51.547506 | C24: =Assumptions!$C$10*(Assumptions!$C$63*C$18+Assumptions!$C$64-$B24)-Assumptions!$C$44 -> -24834.364 | D24: =Assumptions!$C$10*(Assumptions!$C$63*D$18+Assumptions!$C$64-$B24)-Assumptions!$C$44 -> -21759.425 | E24: =Assumptions!$C$10*(Assumptions!$C$63*E$18+Assumptions!$C$64-$B24)-Assumptions!$C$44 -> -18684.486 | F24: =Assumptions!$C$10*(Assumptions!$C$63*F$18+Assumptions!$C$64-$B24)-Assumptions!$C$44 -> -15609.546 | G24: =Assumptions!$C$10*(Assumptions!$C$63*G$18+Assumptions!$C$64-$B24)-Assumptions!$C$44 -> -12534.607 | H24: =Assumptions!$C$10*(Assumptions!$C$63*H$18+Assumptions!$C$64-$B24)-Assumptions!$C$44 -> -9459.6681 | I24: =Assumptions!$C$10*(Assumptions!$C$63*I$18+Assumptions!$C$64-$B24)-Assumptions!$C$44 -> -6384.7289
A25: =A24+Assumptions!$C$60 -> 0.3 | B25: =Assumptions!$C$41*(1+A25) -> 55.843131 | C25: =Assumptions!$C$10*(Assumptions!$C$63*C$18+Assumptions!$C$64-$B25)-Assumptions!$C$44 -> -29954.75 | D25: =Assumptions!$C$10*(Assumptions!$C$63*D$18+Assumptions!$C$64-$B25)-Assumptions!$C$44 -> -26879.81 | E25: =Assumptions!$C$10*(Assumptions!$C$63*E$18+Assumptions!$C$64-$B25)-Assumptions!$C$44 -> -23804.871 | F25: =Assumptions!$C$10*(Assumptions!$C$63*F$18+Assumptions!$C$64-$B25)-Assumptions!$C$44 -> -20729.932 | G25: =Assumptions!$C$10*(Assumptions!$C$63*G$18+Assumptions!$C$64-$B25)-Assumptions!$C$44 -> -17654.993 | H25: =Assumptions!$C$10*(Assumptions!$C$63*H$18+Assumptions!$C$64-$B25)-Assumptions!$C$44 -> -14580.054 | I25: =Assumptions!$C$10*(Assumptions!$C$63*I$18+Assumptions!$C$64-$B25)-Assumptions!$C$44 -> -11505.114

Sheet Lever ranking
A1: Lever ranking: effect of a favourable change in each lever (INR per store per day)
A2: One lever changes at a time, all others at base. Ranks profit impact only, not how easy each change would be. Modeled scenario estimates, not company measurements.
A4: Size of favourable change applied to each lever | B4: =Assumptions!$C$61 -> 0.1
A5: Base store contribution per day (INR) | B5: =Assumptions!$C$68 -> -8443.7145
A7: Lever | B7: Change applied | C7: Store contribution per day after change | D7: Change vs base, INR/day | E7: Share of base daily loss closed | F7: Contribution per order after change, INR | G7: Rank
A8: Order value up | B8: =B$4 -> 0.1 | C8: =Assumptions!$C$10*(Assumptions!$C$63*Assumptions!$C$9*(1+B8)+Assumptions!$C$64-Assumptions!$C$41)-Assumptions!$C$44 -> -2293.8361 | D8: =C8-$B$5 -> 6149.8784 | E8: =IF($B$5>=0,"n/a",D8/-$B$5) -> 0.72833803 | F8: =C8/Assumptions!$C$10 -> -1.9243592 | G8: =RANK(D8,$D$8:$D$11)+COUNTIF($D$7:D7,D8) -> 1
A9: Orders per day up | B9: =B$4 -> 0.1 | C9: =Assumptions!$C$10*(1+B9)*(Assumptions!$C$63*Assumptions!$C$9+Assumptions!$C$64-Assumptions!$C$41)-Assumptions!$C$44 -> -6087.845 | D9: =C9-$B$5 -> 2355.8695 | E9: =IF($B$5>=0,"n/a",D9/-$B$5) -> 0.27900867 | F9: =C9/(Assumptions!$C$10*(1+B9)) -> -4.6429568 | G9: =RANK(D9,$D$8:$D$11)+COUNTIF($D$7:D8,D9) -> 4
A10: Delivery cost per order down | B10: =-B$4 -> -0.1 | C10: =Assumptions!$C$10*(Assumptions!$C$63*Assumptions!$C$9+Assumptions!$C$64-Assumptions!$C$41*(1+B10))-Assumptions!$C$44 -> -3323.3289 | D10: =C10-$B$5 -> 5120.3856 | E10: =IF($B$5>=0,"n/a",D10/-$B$5) -> 0.60641387 | F10: =C10/Assumptions!$C$10 -> -2.7880276 | G10: =RANK(D10,$D$8:$D$11)+COUNTIF($D$7:D9,D10) -> 2
A11: Ad income per order up | B11: =B$4 -> 0.1 | C11: =Assumptions!$C$10*(Assumptions!$C$63*Assumptions!$C$9+Assumptions!$C$64+Assumptions!$C$38*B11-Assumptions!$C$41)-Assumptions!$C$44 -> -6052.396 | D11: =C11-$B$5 -> 2391.3185 | E11: =IF($B$5>=0,"n/a",D11/-$B$5) -> 0.28320693 | F11: =C11/Assumptions!$C$10 -> -5.0775134 | G11: =RANK(D11,$D$8:$D$11)+COUNTIF($D$7:D10,D11) -> 3
A13: Ranked, largest profit impact first
A14: Rank | B14: Lever | C14: Change vs base, INR/day | D14: Share of base daily loss closed
A15: =ROWS($A$15:A15) -> 1 | B15: =INDEX($A$8:$A$11,MATCH(A15,$G$8:$G$11,0)) -> Order value up | C15: =INDEX($D$8:$D$11,MATCH(A15,$G$8:$G$11,0)) -> 6149.8784 | D15: =INDEX($E$8:$E$11,MATCH(A15,$G$8:$G$11,0)) -> 0.72833803
A16: =ROWS($A$15:A16) -> 2 | B16: =INDEX($A$8:$A$11,MATCH(A16,$G$8:$G$11,0)) -> Delivery cost per order down | C16: =INDEX($D$8:$D$11,MATCH(A16,$G$8:$G$11,0)) -> 5120.3856 | D16: =INDEX($E$8:$E$11,MATCH(A16,$G$8:$G$11,0)) -> 0.60641387
A17: =ROWS($A$15:A17) -> 3 | B17: =INDEX($A$8:$A$11,MATCH(A17,$G$8:$G$11,0)) -> Ad income per order up | C17: =INDEX($D$8:$D$11,MATCH(A17,$G$8:$G$11,0)) -> 2391.3185 | D17: =INDEX($E$8:$E$11,MATCH(A17,$G$8:$G$11,0)) -> 0.28320693
A18: =ROWS($A$15:A18) -> 4 | B18: =INDEX($A$8:$A$11,MATCH(A18,$G$8:$G$11,0)) -> Orders per day up | C18: =INDEX($D$8:$D$11,MATCH(A18,$G$8:$G$11,0)) -> 2355.8695 | D18: =INDEX($E$8:$E$11,MATCH(A18,$G$8:$G$11,0)) -> 0.27900867
